{"filename": "python-zope-exceptions-5.1-1-any.pkg.tar.zst", "name": "python-zope-exceptions", "base": "python-zope-exceptions", "version": "5.1-1", "desc": "Generic exceptions and implementations for Zope", "csize": "37666", "isize": "226565", "sha256sum": "f732e01757b4c97f3895c24e4b6b819f58c7b90ec5f4d8e66cfc902e888d073d", "pgpsig": "iQIzBAABCAAdFiEEtZcfLFwQqaCMYAMPeGxj8zDXy5IFAmbCLo0ACgkQeGxj8zDXy5LJqQ//XWPGcmvWIxnsiAL5zrlfGUkAHkZU77wlLZIR0fbVFcLMFVzQJBgQlHC91IHP+PP9a4lhBtUECNdG1UGHxpn5qIbtPWbSBMDhuxKUl7SrYVjPdDU5EEWYKq4PrbqZMm7l6CcWSLZqFF8zBbxNYj7i4KMMZl4dlKl9Lm0zB4ANo69VeWqSaQ/nSWDimLJjYmCkteFzyQVgDRZZ8/Vd1bJ/6jvhksegmWvgL+uYwNJ4BwNW6AqFs6gELqmjRvPR/uD+2Dya7B8nFnQ8O+CvdEqMBYdLw+MuqNev6FsfKtm9x+t2K2BoW5ASpIZ6PWSKKnA1Wwp61mmYHKJVplNHVTJ1xp5K9wXqnpuI6xvq0QdcxmKdsPYuJw4lQmbPXK/TPdM43VNoMi4hgYLTnzbz9Djdia8oA0bWonE++2SHHTDO13258rfQO4EiXiH4HIxkmWIS3YHjaDyZ857XjRlFxWuY5WlAXkegM8j2DpOs7yMeeOX0Ij0vjMjtWHkGGrWtJrwjt6fWYOfW4FpgGtI886o1i/LaW9Ll4YjNhqMXw2BoGX9ZLwKkFkNwMFlV8gbrr9RLcvrsDgb4vVDHvkj0fHKESmvj3nsBlobfuwGynYA5/lSJB+SIBEFjwkI06SUix9xRi0UbYYHKPN/n5Ui/9wrcaq/z78P4qvMoobUX+SseiLk=", "url": "https://github.com/zopefoundation/zope.exceptions", "license": "ZPL", "arch": "any", "builddate": "1724001902", "packager": "Felix Yan <felixonmars@archlinux.org>", "depends": ["python-setuptools", "python-zope-interface"], "makedepends": ["git", "python-setuptools", "python-zope-interface"], "checkdepends": ["python-zope-testrunner"]}