{"filename": "python-zope-exceptions-4.6-3-any.pkg.tar.xz", "name": "python-zope-exceptions", "base": "python-zope-exceptions", "version": "4.6-3", "desc": "Generic exceptions and implementations for Zope", "csize": "36848", "isize": "247277", "md5sum": "2a19f301ab5a241352c8b0c0cf17e3e9", "sha256sum": "c50c44526473a7dce588174776af003dec72d45cf83eb88e31c8df0d5ccbb0b4", "pgpsig": "iQIzBAABCAAdFiEEaLNTfzmjE7PldNBndxk/FSvb5qYFAmRXPfkACgkQdxk/FSvb5qY7tA/+Kf8Vi0naQTQJq6Gc+KIj5pmQyAzBlbLAOZjxHlBml954BGsWF6PqK7Zq0JfQmjB5EuNurgQrJh00t7f30KTOFcy3MpoBpLEGNfqDZIUWmfeofm9zIE7ftTlLh/EzGceonqk0sA8ge25RFvrn1jV1K+9WVBOx73j7sWW/vFeOb+olnGWZeRkmqhawiq2294MI7cij3UhjfOs5+GcnSy2LHy0CaQzGCxxHeLs18Ej8fjo+G/CtdkoMl+dd6NImL84q50q29hnCfuYWohl1OjbLX30LHyM+nT1J4ApUPwNbO1Lrn6a1bb1Gyncbyt+Hb/Mg74gbGCkG5nG3rIW8RGoDgFSQu3tkrQCWaTQ0Z88X9W95r2WQmmKxiNE1I5io8DPzuYIUkoiOOkUjp4P1Gw67JwM0t/ZhtT0rqP2vSfylVug3CYUohjOZzqXZvQft1eWyqu5gAztXrZmuYpVkF87WP5xt7PY36nVjv3epx+H+U5D48nYmSISSUSR/dK4FITL84/ynVqJLSeRQaUT8M6sVjPSf72x7YTwNBCYyWKO9Npg++EuT99yRAQ0S2oQ4b4xDIgA1DfIOsDLaSgvS3nw0Kmwz4P26SCDpnV6whRGQmoZ9CxzN2kpItQDfOkhG4SpBN/VUYtUa7ulRdQQY+Xoq7PeULiB5BnUDvZJXvbFqlgk=", "url": "https://github.com/zopefoundation/zope.exceptions", "license": "ZPL", "arch": "any", "builddate": "1683439087", "packager": "Arch Linux ARM Build System <builder+seattle@archlinuxarm.org>", "depends": ["python-setuptools", "python-zope-interface"], "makedepends": ["python-setuptools", "python-zope-interface"], "checkdepends": ["python-zope-testrunner"], "tokens": ["python-zope-exceptions", "python-zope-exceptions_aarch64", "python-zope-exceptions_unstable", "python-zope-exceptions_aarch64_unstable"]}