{"filename": "python-zope-exceptions-5.0.1-1-any.pkg.tar.xz", "name": "python-zope-exceptions", "base": "python-zope-exceptions", "version": "5.0.1-1", "desc": "Generic exceptions and implementations for Zope", "csize": "36124", "isize": "244321", "md5sum": "f2cb15da79c6b8299a51f9184822c810", "sha256sum": "9e8e8d59fe0084c09872b2c5bfcbea04654f3c05cdef5cd7d05b6e00c62b6bb4", "pgpsig": "iQIzBAABCAAdFiEEaLNTfzmjE7PldNBndxk/FSvb5qYFAmVVxvgACgkQdxk/FSvb5qbfvg/+NfGftRes+KKISVbangb9T09/bTCe58UFz7UW23GN1KanglbLTfHX5cot/cZY3vS9eN/yk3/FpZBhB/2aSXl09RHsy2piYh+/YC0ZHjFOHpZRTUbhLZXmJgJ/8DeGyQzdfL/0bXJ84FR0bmN8gFKqgYGkTiHzITp0uce1bcPQ83OBjG6KPyad3h7QKdayk4X2wNOA25/YrXM0Hx26OQrqVdvgNVwByMTXMKopUCFvj79wQCefRrxbVVJbz+3dFhc8woQ2f2sgDHF7zUwR4h1IN/ojfdn5dpyAQyzsK79jpkmFu4BOv2RMpWmZsJzEZ+vX0MxUvY68Gt4D3Qeszc1YlcgrWhFXTOVXpDmRsJsbh++MRngWbZgR7zFex3W4rzBuFV6l7Uybd2+KxLUJv6nPCq3DegkNUakIs2xvzZGUol1puJUutCAQi/s0VL11/we+24NLcTpnmFPtPRzdzflWLGHQNpnq48e4+hYM1onnHyAR2jB6ogmXFZTWK8JDPlkmf1Bq44V3f/mNkWsgczPihYRDfUFJaxe7gGVpLjaJ1cATgI31/2u+gJRJY9V76lOhyQ0q4budWQdPQRAhsa+5ZC4ZlqzAHOu4NUGqwboRJh42+BUcXCu17wjJyKD3kJfOmFBRjsIf6/rP82sR4ccRcnClZUbXAt5jsfH75Klj08w=", "url": "https://github.com/zopefoundation/zope.exceptions", "license": "ZPL", "arch": "any", "builddate": "1700120300", "packager": "Arch Linux ARM Build System <builder+seattle@archlinuxarm.org>", "depends": ["python-setuptools", "python-zope-interface"], "makedepends": ["python-setuptools", "python-zope-interface"], "checkdepends": ["python-zope-testrunner"], "tokens": ["python-zope-exceptions", "python-zope-exceptions_aarch64", "python-zope-exceptions_unstable", "python-zope-exceptions_aarch64_unstable"]}