{"filename": "python-zope-exceptions-5.0-1-any.pkg.tar.zst", "name": "python-zope-exceptions", "base": "python-zope-exceptions", "version": "5.0-1", "desc": "Generic exceptions and implementations for Zope", "csize": "38430", "isize": "243243", "md5sum": "483edf7823339b0fddcbf9874ebc51f7", "sha256sum": "0149f69f17038bb0f4953cdc729ccdc44589943e02c4fd45f92a6fc4b8d43ef8", "pgpsig": "iQIzBAABCAAdFiEEtZcfLFwQqaCMYAMPeGxj8zDXy5IFAmVU+Z8ACgkQeGxj8zDXy5LLjA/9EWgAvO3jtN4MylZGfaCNL1iCiqUwK1QiR6jKMmOkuav+8sKsgg9BuKdMQJVuq0VwchDmUm/F7tFj5Z76DxuY1tZHPs98O4pMDRBCU3b6rJm0pCroNqVgYE52JYL7bZ8e9lQlzazVr1k4g7egI486PuC+in5VfdwywwixkirQGvgRMQdtestX38JOxhDH69mXITtdG60aQYTsxA/Wtax8oo9NR4afEYj9YVB5BwxPn82m9OlqmpCQGu/8p0FaIKLmyyzW9GQwwK8rUgKdA0hSr0iXPcoRiNXBatFncCKDuNBrw0SPd3yr86pweCqK0do1bemqnHVcgmRWK7GNL79DEvAEa/JVVWveHZ3SxIbyN0WiPNT/W2Bak1Xhwb935mGJOhxx9O2E1lBXyP5RXaaic/uqI0XcpA7++vkHdNWTEqWPZp1hzKqo+z+R320nfl9VLeZE1aBesp5OtS6EcvWvVJOeoP+jS95AWstW+xjq5Q0ACL/iOXMTUK3bhtCGpnHTk9gSJ8Z1qliKLh7Nu1AULUmW4q6+C+9/2Fm846tdQTV3uZ6ckgFoGp6fedPT2U+IgMy7BElv4jBjrpZam4pnkEZ8XIrXUngQH3Za44EpWJuYxgyDpeDmI3L2x9zcDKGzul5ZpcRGaRbKPVJEzWLyrxMWRCiMOuQg39ZlQ1+7Bl4=", "url": "https://github.com/zopefoundation/zope.exceptions", "license": "ZPL", "arch": "any", "builddate": "1700067711", "packager": "Felix Yan <felixonmars@archlinux.org>", "depends": ["python-setuptools", "python-zope-interface"], "makedepends": ["python-setuptools", "python-zope-interface"], "checkdepends": ["python-zope-testrunner"], "tokens": ["python-zope-exceptions", "python-zope-exceptions_x86_64", "python-zope-exceptions_unstable", "python-zope-exceptions_x86_64_unstable"]}